test0
test0,1
test1
connected using socket
packet length: 74
call[1]: _read_packet (line 713)
call[2]: _get_server_information (line 1055)
call[3]: connect (line 632)
call[4]: __init__ (line 353)
call[5]: connect (line 584)
call[6]: connect (line 578)
------------------------------------------------------------------
0A 38 2E 30 2E 32 36 00 1A 00 00 00 6E 05 66 43  .8.0.26.....n.fC
4F 40 54 05 00 FF FF FF 02 00 FF CF 15 00 00 00  O@T.............
00 00 00 00 00 00 00 43 52 6E 1C 68 70 05 0D 6B  .......CRn.hp..k
14 07 31 00 63 61 63 68 69 6E 67 5F 73 68 61 32  ..1.caching_sha2
5F 70 61 73 73 77 6F 72 64 00                    _password.
------------------------------------------------------------------

server_status: 2
salt_len: 21
caching_sha2: trying fast path
packet length: 154
call[1]: write_packet (line 679)
call[2]: _request_authentication (line 906)
call[3]: connect (line 633)
call[4]: __init__ (line 353)
call[5]: connect (line 584)
call[6]: connect (line 578)
------------------------------------------------------------------
96 00 00 01 0F A2 3A 00 FF FF FF 00 2D 00 00 00  ......:.....-...
00 00 00 00 00 00 00 00 00 00 00 00 00 00 00 00  ................
00 00 00 00 72 6F 6F 74 00 20 93 6A 8B B6 22 05  ....root. .j..".
20 EF 97 DA A6 B4 DF 7D F4 48 42 1A 61 8E 40 0E   ......}.HB.a.@.
D2 EF 02 38 F8 24 23 4D 68 54 63 72 69 6D 65 73  ...8.$#MhTcrimes
00 63 61 63 68 69 6E 67 5F 73 68 61 32 5F 70 61  .caching_sha2_pa
73 73 77 6F 72 64 00 32 0C 5F 63 6C 69 65 6E 74  ssword.2._client
5F 6E 61 6D 65 07 70 79 6D 79 73 71 6C 04 5F 70  _name.pymysql._p
69 64 01 31 0F 5F 63 6C 69 65 6E 74 5F 76 65 72  id.1._client_ver
73 69 6F 6E 05 31 2E 30 2E 32                    sion.1.0.2
------------------------------------------------------------------

packet length: 2
call[1]: _read_packet (line 713)
call[2]: _request_authentication (line 907)
call[3]: connect (line 633)
call[4]: __init__ (line 353)
call[5]: connect (line 584)
call[6]: connect (line 578)
------------------------------------------------------------------
01 04                                            ..
------------------------------------------------------------------

received extra data
packet length: 5
call[1]: write_packet (line 679)
call[2]: _roundtrip (line 119)
call[3]: caching_sha2_password_auth (line 255)
call[4]: _request_authentication (line 932)
call[5]: connect (line 633)
call[6]: __init__ (line 353)
------------------------------------------------------------------
01 00 00 03 02                                   .....
------------------------------------------------------------------

packet length: 452
call[1]: _read_packet (line 713)
call[2]: _roundtrip (line 120)
call[3]: caching_sha2_password_auth (line 255)
call[4]: _request_authentication (line 932)
call[5]: connect (line 633)
call[6]: __init__ (line 353)
------------------------------------------------------------------
01 2D 2D 2D 2D 2D 42 45 47 49 4E 20 50 55 42 4C  .-----BEGIN PUBL
49 43 20 4B 45 59 2D 2D 2D 2D 2D 0A 4D 49 49 42  IC KEY-----.MIIB
49 6A 41 4E 42 67 6B 71 68 6B 69 47 39 77 30 42  IjANBgkqhkiG9w0B
41 51 45 46 41 41 4F 43 41 51 38 41 4D 49 49 42  AQEFAAOCAQ8AMIIB
43 67 4B 43 41 51 45 41 76 44 72 6B 44 31 78 77  CgKCAQEAvDrkD1xw
61 74 43 72 63 30 5A 4B 53 4D 6A 6F 0A 39 39 64  atCrc0ZKSMjo.99d
72 61 62 65 45 56 4A 4C 62 52 45 31 35 74 73 5A  rabeEVJLbRE15tsZ
72 6D 68 69 7A 4F 57 6F 32 61 44 69 71 6C 39 64  rmhizOWo2aDiql9d
78 71 4F 34 51 43 41 4F 50 76 72 72 31 32 35 37  xqO4QCAOPvrr1257
75 46 75 4B 75 7A 33 70 73 77 61 56 74 0A 4D 7A  uFuKuz3pswaVt.Mz
69 68 2F 6D 6B 2F 58 72 4A 71 38 54 63 73 78 57  ih/mk/XrJq8TcsxW
36 72 62 6D 32 6C 6F 68 54 69 4D 48 70 53 30 33  6rbm2lohTiMHpS03
6B 59 46 34 4D 2F 4B 32 6D 49 36 32 53 4B 72 2F  kYF4M/K2mI62SKr/
69 50 51 58 39 49 76 6B 36 4F 4F 79 59 41 0A 6F  iPQX9Ivk6OOyYA.o
6A 6D 52 42 4E 41 45 62 39 4C 53 44 33 2F 35 48  jmRBNAEb9LSD3/5H
45 74 45 69 48 54 6C 77 67 51 74 51 62 46 33 48  EtEiHTlwgQtQbF3H
------------------------------------------------------------------

Traceback (most recent call last):
  File "/webapp/app.py", line 24, in <module>
    crimes = pd.read_sql('Chicago_Crimes_sample', con=engine.connect())
  File "/usr/local/lib/python3.8/site-packages/sqlalchemy/engine/base.py", line 3166, in connect
    return self._connection_cls(self, close_with_result=close_with_result)
  File "/usr/local/lib/python3.8/site-packages/sqlalchemy/engine/base.py", line 96, in __init__
    else engine.raw_connection()
  File "/usr/local/lib/python3.8/site-packages/sqlalchemy/engine/base.py", line 3245, in raw_connection
    return self._wrap_pool_connect(self.pool.connect, _connection)
  File "/usr/local/lib/python3.8/site-packages/sqlalchemy/engine/base.py", line 3212, in _wrap_pool_connect
    return fn()
  File "/usr/local/lib/python3.8/site-packages/sqlalchemy/pool/base.py", line 307, in connect
    return _ConnectionFairy._checkout(self)
  File "/usr/local/lib/python3.8/site-packages/sqlalchemy/pool/base.py", line 767, in _checkout
    fairy = _ConnectionRecord.checkout(pool)
  File "/usr/local/lib/python3.8/site-packages/sqlalchemy/pool/base.py", line 425, in checkout
    rec = pool._do_get()
  File "/usr/local/lib/python3.8/site-packages/sqlalchemy/pool/impl.py", line 146, in _do_get
    self._dec_overflow()
  File "/usr/local/lib/python3.8/site-packages/sqlalchemy/util/langhelpers.py", line 70, in __exit__
    compat.raise_(
  File "/usr/local/lib/python3.8/site-packages/sqlalchemy/util/compat.py", line 207, in raise_
    raise exception
  File "/usr/local/lib/python3.8/site-packages/sqlalchemy/pool/impl.py", line 143, in _do_get
    return self._create_connection()
  File "/usr/local/lib/python3.8/site-packages/sqlalchemy/pool/base.py", line 253, in _create_connection
    return _ConnectionRecord(self)
  File "/usr/local/lib/python3.8/site-packages/sqlalchemy/pool/base.py", line 368, in __init__
    self.__connect()
  File "/usr/local/lib/python3.8/site-packages/sqlalchemy/pool/base.py", line 611, in __connect
    pool.logger.debug("Error on connect(): %s", e)
  File "/usr/local/lib/python3.8/site-packages/sqlalchemy/util/langhelpers.py", line 70, in __exit__
    compat.raise_(
  File "/usr/local/lib/python3.8/site-packages/sqlalchemy/util/compat.py", line 207, in raise_
    raise exception
  File "/usr/local/lib/python3.8/site-packages/sqlalchemy/pool/base.py", line 605, in __connect
    connection = pool._invoke_creator(self)
  File "/usr/local/lib/python3.8/site-packages/sqlalchemy/engine/create.py", line 578, in connect
    return dialect.connect(*cargs, **cparams)
  File "/usr/local/lib/python3.8/site-packages/sqlalchemy/engine/default.py", line 584, in connect
    return self.dbapi.connect(*cargs, **cparams)
  File "/usr/local/lib/python3.8/site-packages/pymysql/connections.py", line 353, in __init__
    self.connect()
  File "/usr/local/lib/python3.8/site-packages/pymysql/connections.py", line 633, in connect
    self._request_authentication()
  File "/usr/local/lib/python3.8/site-packages/pymysql/connections.py", line 932, in _request_authentication
    auth_packet = _auth.caching_sha2_password_auth(self, auth_packet)
  File "/usr/local/lib/python3.8/site-packages/pymysql/_auth.py", line 265, in caching_sha2_password_auth
    data = sha2_rsa_encrypt(conn.password, conn.salt, conn.server_public_key)
  File "/usr/local/lib/python3.8/site-packages/pymysql/_auth.py", line 143, in sha2_rsa_encrypt
    raise RuntimeError(
RuntimeError: 'cryptography' package is required for sha256_password or caching_sha2_password auth methods
